Workbook

Sheet Table1
A1: timestamp | B1: mode | C1: framework | D1: n_resources | E1: component | F1: cpu_millicores | G1: mem_mib
A2: 46218.883 | B2: at-rest | C2: all | D2: 0 | E2: crossplane-core | F2: 3 | G2: 187
A3: 46218.883 | B3: at-rest | C3: all | D3: 0 | E3: provider-kafka | F3: 2 | G3: 71
A4: 46218.883 | B4: at-rest | C4: all | D4: 0 | E4: provider-kubernetes | F4: 2 | G4: 74
A5: 46218.883 | B5: at-rest | C5: all | D5: 0 | E5: function-patch-and-transform | F5: 1 | G5: 52
A6: 46218.883 | B6: at-rest | C6: all | D6: 0 | E6: kubebuilder-controller | F6: 0 | G6: 51.5
A7: 46218.883 | B7: at-rest | C7: all | D7: 0 | E7: crossplane-core | F7: 3 | G7: 187
A8: 46218.883 | B8: at-rest | C8: all | D8: 0 | E8: provider-kafka | F8: 2 | G8: 71
A9: 46218.883 | B9: at-rest | C9: all | D9: 0 | E9: provider-kubernetes | F9: 2 | G9: 74
A10: 46218.883 | B10: at-rest | C10: all | D10: 0 | E10: function-patch-and-transform | F10: 1 | G10: 52
A11: 46218.883 | B11: at-rest | C11: all | D11: 0 | E11: kubebuilder-controller | F11: 0 | G11: 51.5
A12: 46218.883 | B12: at-rest | C12: all | D12: 0 | E12: crossplane-core | F12: 3 | G12: 187
A13: 46218.883 | B13: at-rest | C13: all | D13: 0 | E13: provider-kafka | F13: 2 | G13: 71
... A1343: 46218.936 | B1343: scale | C1343: kubebuilder | D1343: 1000 | E1343: kubebuilder-controller | F1343: 0 | G1343: 78.9

Sheet rest kb
A1: timestamp | B1: mode | C1: framework | D1: n_resources | E1: component | F1: cpu_millicores | G1: mem_mib
A2: 46219.204 | B2: at-rest | C2: all | D2: 0 | E2: crossplane-core | F2: 3 | G2: 762
A3: 46219.204 | B3: at-rest | C3: all | D3: 0 | E3: provider-kafka | F3: 2 | G3: 119
A4: 46219.204 | B4: at-rest | C4: all | D4: 0 | E4: provider-kubernetes | F4: 1 | G4: 170
A5: 46219.204 | B5: at-rest | C5: all | D5: 0 | E5: function-patch-and-transform | F5: 0 | G5: 40
A6: 46219.204 | B6: at-rest | C6: all | D6: 0 | E6: kubebuilder-controller | F6: 0 | G6: 46
A7: 46219.204 | B7: at-rest | C7: all | D7: 0 | E7: crossplane-core | F7: 3 | G7: 762
A8: 46219.204 | B8: at-rest | C8: all | D8: 0 | E8: provider-kafka | F8: 2 | G8: 119
A9: 46219.204 | B9: at-rest | C9: all | D9: 0 | E9: provider-kubernetes | F9: 2 | G9: 170
A10: 46219.204 | B10: at-rest | C10: all | D10: 0 | E10: function-patch-and-transform | F10: 0 | G10: 40
A11: 46219.204 | B11: at-rest | C11: all | D11: 0 | E11: kubebuilder-controller | F11: 0 | G11: 46
A12: 46219.204 | B12: at-rest | C12: all | D12: 0 | E12: crossplane-core | F12: 7 | G12: 762
A13: 46219.204 | B13: at-rest | C13: all | D13: 0 | E13: provider-kafka | F13: 2 | G13: 119
... A61: 46219.205 | B61: at-rest | C61: all | D61: 0 | E61: kubebuilder-controller | F61: 0 | G61: 46.1

Sheet rest
A2: timestamp | B2: mode | C2: framework | D2: n_resources | E2: component | F2: cpu_millicores | G2: mem_mib | K2: timestamp | L2: mode | M2: framework | N2: n_resources | O2: component | P2: cpu_millicores | Q2: mem_mib
A3: 46218.883 | B3: at-rest | C3: all | D3: 0 | E3: crossplane-core | F3: 3 | G3: 187 | K3: 2026-07-16T02:53:23+00:00 | L3: at-rest | M3: all | N3: 0 | O3: crossplane-core | P3: 3 | Q3: 762
A4: 46218.883 | B4: at-rest | C4: all | D4: 0 | E4: crossplane-core | F4: 3 | G4: 187 | K4: 2026-07-16T02:53:24+00:00 | L4: at-rest | M4: all | N4: 0 | O4: provider-kafka | P4: 2 | Q4: 119
A5: 46218.883 | B5: at-rest | C5: all | D5: 0 | E5: crossplane-core | F5: 3 | G5: 187 | K5: 2026-07-16T02:53:24+00:00 | L5: at-rest | M5: all | N5: 0 | O5: provider-kubernetes | P5: 1 | Q5: 170
A6: 46218.883 | B6: at-rest | C6: all | D6: 0 | E6: crossplane-core | F6: 3 | G6: 187 | K6: 2026-07-16T02:53:25+00:00 | L6: at-rest | M6: all | N6: 0 | O6: function-patch-and-transform | P6: 0 | Q6: 40
A7: 46218.883 | B7: at-rest | C7: all | D7: 0 | E7: crossplane-core | F7: 3 | G7: 187 | K7: 2026-07-16T02:53:25+00:00 | L7: at-rest | M7: all | N7: 0 | O7: kubebuilder-controller | P7: 0 | Q7: 46
A8: 46218.883 | B8: at-rest | C8: all | D8: 0 | E8: crossplane-core | F8: 3 | G8: 187 | K8: 2026-07-16T02:53:31+00:00 | L8: at-rest | M8: all | N8: 0 | O8: crossplane-core | P8: 3 | Q8: 762
A9: 46218.884 | B9: at-rest | C9: all | D9: 0 | E9: crossplane-core | F9: 6 | G9: 187 | K9: 2026-07-16T02:53:31+00:00 | L9: at-rest | M9: all | N9: 0 | O9: provider-kafka | P9: 2 | Q9: 119
A10: 46218.884 | B10: at-rest | C10: all | D10: 0 | E10: crossplane-core | F10: 6 | G10: 187 | K10: 2026-07-16T02:53:32+00:00 | L10: at-rest | M10: all | N10: 0 | O10: provider-kubernetes | P10: 2 | Q10: 170
A11: 46218.884 | B11: at-rest | C11: all | D11: 0 | E11: crossplane-core | F11: 3 | G11: 187 | K11: 2026-07-16T02:53:32+00:00 | L11: at-rest | M11: all | N11: 0 | O11: function-patch-and-transform | P11: 0 | Q11: 40
A12: 46218.884 | B12: at-rest | C12: all | D12: 0 | E12: crossplane-core | F12: 3 | G12: 187 | K12: 2026-07-16T02:53:33+00:00 | L12: at-rest | M12: all | N12: 0 | O12: kubebuilder-controller | P12: 0 | Q12: 46
A13: 46218.884 | B13: at-rest | C13: all | D13: 0 | E13: crossplane-core | F13: 3 | G13: 187 | K13: 2026-07-16T02:53:39+00:00 | L13: at-rest | M13: all | N13: 0 | O13: crossplane-core | P13: 7 | Q13: 762
A14: 46218.884 | B14: at-rest | C14: all | D14: 0 | E14: crossplane-core | F14: 3 | G14: 187 | K14: 2026-07-16T02:53:39+00:00 | L14: at-rest | M14: all | N14: 0 | O14: provider-kafka | P14: 2 | Q14: 119
K15: 2026-07-16T02:53:39+00:00 | L15: at-rest | M15: all | N15: 0 | O15: provider-kubernetes | P15: 2 | Q15: 170
K16: 2026-07-16T02:53:40+00:00 | L16: at-rest | M16: all | N16: 0 | O16: function-patch-and-transform | P16: 0 | Q16: 40
K17: 2026-07-16T02:53:40+00:00 | L17: at-rest | M17: all | N17: 0 | O17: kubebuilder-controller | P17: 0 | Q17: 46
K18: 2026-07-16T02:53:46+00:00 | L18: at-rest | M18: all | N18: 0 | O18: crossplane-core | P18: 7 | Q18: 762
K19: 2026-07-16T02:53:46+00:00 | L19: at-rest | M19: all | N19: 0 | O19: provider-kafka | P19: 2 | Q19: 119
K20: 2026-07-16T02:53:47+00:00 | L20: at-rest | M20: all | N20: 0 | O20: provider-kubernetes | P20: 2 | Q20: 170
K21: 2026-07-16T02:53:47+00:00 | L21: at-rest | M21: all | N21: 0 | O21: function-patch-and-transform | P21: 1 | Q21: 40
A22: timestamp | B22: mode | C22: framework | D22: n_resources | E22: component | F22: cpu_millicores | G22: mem_mib | K22: 2026-07-16T02:53:47+00:00 | L22: at-rest | M22: all | N22: 0 | O22: kubebuilder-controller | P22: 10 | Q22: 46
A23: 46218.883 | B23: at-rest | C23: all | D23: 0 | E23: function-patch-and-transform | F23: 1 | G23: 52 | K23: 2026-07-16T02:53:53+00:00 | L23: at-rest | M23: all | N23: 0 | O23: crossplane-core | P23: 3 | Q23: 762
A24: 46218.883 | B24: at-rest | C24: all | D24: 0 | E24: function-patch-and-transform | F24: 1 | G24: 52 | K24: 2026-07-16T02:53:54+00:00 | L24: at-rest | M24: all | N24: 0 | O24: provider-kafka | P24: 2 | Q24: 119
A25: 46218.883 | B25: at-rest | C25: all | D25: 0 | E25: function-patch-and-transform | F25: 1 | G25: 52 | K25: 2026-07-16T02:53:54+00:00 | L25: at-rest | M25: all | N25: 0 | O25: provider-kubernetes | P25: 2 | Q25: 170
A26: 46218.883 | B26: at-rest | C26: all | D26: 0 | E26: function-patch-and-transform | F26: 1 | G26: 52 | K26: 2026-07-16T02:53:54+00:00 | L26: at-rest | M26: all | N26: 0 | O26: function-patch-and-transform | P26: 1 | Q26: 40
A27: 46218.883 | B27: at-rest | C27: all | D27: 0 | E27: function-patch-and-transform | F27: 0 | G27: 52 | K27: 2026-07-16T02:53:55+00:00 | L27: at-rest | M27: all | N27: 0 | O27: kubebuilder-controller | P27: 0 | Q27: 46
A28: 46218.884 | B28: at-rest | C28: all | D28: 0 | E28: function-patch-and-transform | F28: 0 | G28: 52 | K28: 2026-07-16T02:54:01+00:00 | L28: at-rest | M28: all | N28: 0 | O28: crossplane-core | P28: 3 | Q28: 762
A29: 46218.884 | B29: at-rest | C29: all | D29: 0 | E29: function-patch-and-transform | F29: 1 | G29: 52 | K29: 2026-07-16T02:54:01+00:00 | L29: at-rest | M29: all | N29: 0 | O29: provider-kafka | P29: 2 | Q29: 119
A30: 46218.884 | B30: at-rest | C30: all | D30: 0 | E30: function-patch-and-transform | F30: 1 | G30: 52 | K30: 2026-07-16T02:54:02+00:00 | L30: at-rest | M30: all | N30: 0 | O30: provider-kubernetes | P30: 2 | Q30: 170
A31: 46218.884 | B31: at-rest | C31: all | D31: 0 | E31: function-patch-and-transform | F31: 0 | G31: 52 | K31: 2026-07-16T02:54:02+00:00 | L31: at-rest | M31: all | N31: 0 | O31: function-patch-and-transform | P31: 0 | Q31: 40
A32: 46218.884 | B32: at-rest | C32: all | D32: 0 | E32: function-patch-and-transform | F32: 0 | G32: 52 | K32: 2026-07-16T02:54:02+00:00 | L32: at-rest | M32: all | N32: 0 | O32: kubebuilder-controller | P32: 0 | Q32: 46
A33: 46218.884 | B33: at-rest | C33: all | D33: 0 | E33: function-patch-and-transform | F33: 0 | G33: 52 | K33: 2026-07-16T02:54:08+00:00 | L33: at-rest | M33: all | N33: 0 | O33: crossplane-core | P33: 2 | Q33: 762
A34: 46218.884 | B34: at-rest | C34: all | D34: 0 | E34: function-patch-and-transform | F34: 0 | G34: 52 | K34: 2026-07-16T02:54:09+00:00 | L34: at-rest | M34: all | N34: 0 | O34: provider-kafka | P34: 2 | Q34: 119
K35: 2026-07-16T02:54:09+00:00 | L35: at-rest | M35: all | N35: 0 | O35: provider-kubernetes | P35: 2 | Q35: 170
K36: 2026-07-16T02:54:09+00:00 | L36: at-rest | M36: all | N36: 0 | O36: function-patch-and-transform | P36: 0 | Q36: 40
K37: 2026-07-16T02:54:10+00:00 | L37: at-rest | M37: all | N37: 0 | O37: kubebuilder-controller | P37: 0 | Q37: 46
K38: 2026-07-16T02:54:16+00:00 | L38: at-rest | M38: all | N38: 0 | O38: crossplane-core | P38: 2 | Q38: 762
K39: 2026-07-16T02:54:16+00:00 | L39: at-rest | M39: all | N39: 0 | O39: provider-kafka | P39: 2 | Q39: 119
K40: 2026-07-16T02:54:16+00:00 | L40: at-rest | M40: all | N40: 0 | O40: provider-kubernetes | P40: 2 | Q40: 170
K41: 2026-07-16T02:54:17+00:00 | L41: at-rest | M41: all | N41: 0 | O41: function-patch-and-transform | P41: 0 | Q41: 40
...

Sheet dati
A1: crossplane-core | G1: function-patch-and-transform | M1: provider-kafka | S1: provider-kubernetes | Z1: CROSSPLANE TOTAL | AB1: kubebuilder-controller
A2: timestamp | B2: mode | C2: framework | D2: n_resources | E2: cpu_millicores | F2: mem_mib | G2: timestamp | H2: mode | I2: framework | J2: n_resources | K2: cpu_millicores | L2: mem_mib | M2: timestamp | N2: mode | O2: framework | P2: n_resources | Q2: cpu_millicores | R2: mem_mib | S2: timestamp | T2: mode | U2: framework | V2: n_resources | W2: component | X2: cpu_millicores | Y2: mem_mib | Z2: cpu crossplane | AA2: mem_mib | AB2: timestamp | AC2: mode | AD2: framework | AE2: n_resources | AF2: component | AG2: cpu_millicores | AH2: mem_mib | AI2: crossplane x
A3: 46218.884 | B3: scale-burst | C3: crossplane | D3: 1 | E3: 2 | F3: 187 | G3: 46218.884 | H3: scale-burst | I3: crossplane | J3: 1 | K3: 0 | L3: 52 | M3: 46218.884 | N3: scale-burst | O3: crossplane | P3: 1 | Q3: 2 | R3: 71 | S3: 46218.884 | T3: scale-burst | U3: crossplane | V3: 1 | W3: provider-kubernetes | X3: 2 | Y3: 74 | Z3: =E3+K3+Q3+X3 -> 6 | AA3: =F3+L3+R3+Y3 -> 384 | AB3: 46218.923 | AC3: scale-burst | AD3: kubebuilder | AE3: 10 | AF3: kubebuilder-controller | AG3: 88 | AH3: 56 | AI3: =J3 -> 1
A4: 46218.884 | B4: scale-burst | C4: crossplane | D4: 1 | E4: 2 | F4: 187 | G4: 46218.884 | H4: scale-burst | I4: crossplane | J4: 1 | K4: 0 | L4: 52 | M4: 46218.884 | N4: scale-burst | O4: crossplane | P4: 1 | Q4: 2 | R4: 71 | S4: 46218.884 | T4: scale-burst | U4: crossplane | V4: 1 | W4: provider-kubernetes | X4: 2 | Y4: 74 | Z4: =E4+K4+Q4+X4 -> 6 | AA4: =F4+L4+R4+Y4 -> 384 | AB4: 46218.923 | AC4: scale-burst | AD4: kubebuilder | AE4: 10 | AF4: kubebuilder-controller | AG4: 69 | AH4: 56.1 | AI4: =IF(J4=J3,AI3+1,J4) -> 2
A5: 46218.885 | B5: scale-burst | C5: crossplane | D5: 10 | E5: 3 | F5: 187 | G5: 46218.885 | H5: scale-burst | I5: crossplane | J5: 10 | K5: 0 | L5: 52 | M5: 46218.885 | N5: scale-burst | O5: crossplane | P5: 10 | Q5: 3 | R5: 71 | S5: 46218.885 | T5: scale-burst | U5: crossplane | V5: 10 | W5: provider-kubernetes | X5: 3 | Y5: 74 | Z5: =E5+K5+Q5+X5 -> 9 | AA5: =F5+L5+R5+Y5 -> 384 | AB5: 46218.923 | AC5: scale-burst | AD5: kubebuilder | AE5: 10 | AF5: kubebuilder-controller | AG5: 69 | AH5: 56.2 | AI5: =IF(J5=J4,AI4+1,J5) -> 10
A6: 46218.885 | B6: scale-burst | C6: crossplane | D6: 10 | E6: 3 | F6: 187 | G6: 46218.885 | H6: scale-burst | I6: crossplane | J6: 10 | K6: 0 | L6: 52 | M6: 46218.885 | N6: scale-burst | O6: crossplane | P6: 10 | Q6: 3 | R6: 71 | S6: 46218.885 | T6: scale-burst | U6: crossplane | V6: 10 | W6: provider-kubernetes | X6: 3 | Y6: 74 | Z6: =E6+K6+Q6+X6 -> 9 | AA6: =F6+L6+R6+Y6 -> 384 | AB6: 46218.924 | AC6: scale-burst | AD6: kubebuilder | AE6: 50 | AF6: kubebuilder-controller | AG6: 68 | AH6: 56.2 | AI6: =IF(J6=J5,AI5+1,J6) -> 11
A7: 46218.885 | B7: scale-burst | C7: crossplane | D7: 10 | E7: 4 | F7: 187 | G7: 46218.885 | H7: scale-burst | I7: crossplane | J7: 10 | K7: 8 | L7: 52 | M7: 46218.885 | N7: scale-burst | O7: crossplane | P7: 10 | Q7: 3 | R7: 71 | S7: 46218.885 | T7: scale-burst | U7: crossplane | V7: 10 | W7: provider-kubernetes | X7: 9 | Y7: 74 | Z7: =E7+K7+Q7+X7 -> 24 | AA7: =F7+L7+R7+Y7 -> 384 | AB7: 46218.924 | AC7: scale-burst | AD7: kubebuilder | AE7: 50 | AF7: kubebuilder-controller | AG7: 69 | AH7: 56.3 | AI7: =IF(J7=J6,AI6+1,J7) -> 12
A8: 46218.887 | B8: scale-burst | C8: crossplane | D8: 50 | E8: 3 | F8: 188 | G8: 46218.887 | H8: scale-burst | I8: crossplane | J8: 50 | K8: 1 | L8: 53 | M8: 46218.887 | N8: scale-burst | O8: crossplane | P8: 50 | Q8: 2 | R8: 71 | S8: 46218.887 | T8: scale-burst | U8: crossplane | V8: 50 | W8: provider-kubernetes | X8: 2 | Y8: 74 | Z8: =E8+K8+Q8+X8 -> 8 | AA8: =F8+L8+R8+Y8 -> 386 | AB8: 46218.924 | AC8: scale-burst | AD8: kubebuilder | AE8: 50 | AF8: kubebuilder-controller | AG8: 79 | AH8: 56.4 | AI8: =IF(J8=J7,AI7+1,J8) -> 50
A9: 46218.887 | B9: scale-burst | C9: crossplane | D9: 50 | E9: 3 | F9: 188 | G9: 46218.887 | H9: scale-burst | I9: crossplane | J9: 50 | K9: 24 | L9: 54 | M9: 46218.887 | N9: scale-burst | O9: crossplane | P9: 50 | Q9: 2 | R9: 71 | S9: 46218.887 | T9: scale-burst | U9: crossplane | V9: 50 | W9: provider-kubernetes | X9: 88 | Y9: 74 | Z9: =E9+K9+Q9+X9 -> 117 | AA9: =F9+L9+R9+Y9 -> 387 | AB9: 46218.924 | AC9: scale-burst | AD9: kubebuilder | AE9: 50 | AF9: kubebuilder-controller | AG9: 68 | AH9: 56.4 | AI9: =IF(J9=J8,AI8+1,J9) -> 51
A10: 46218.887 | B10: scale-burst | C10: crossplane | D10: 50 | E10: 33 | F10: 188 | G10: 46218.887 | H10: scale-burst | I10: crossplane | J10: 50 | K10: 24 | L10: 54 | M10: 46218.887 | N10: scale-burst | O10: crossplane | P10: 50 | Q10: 25 | R10: 71 | S10: 46218.887 | T10: scale-burst | U10: crossplane | V10: 50 | W10: provider-kubernetes | X10: 88 | Y10: 74 | Z10: =E10+K10+Q10+X10 -> 170 | AA10: =F10+L10+R10+Y10 -> 387 | AB10: 46218.924 | AC10: scale-burst | AD10: kubebuilder | AE10: 50 | AF10: kubebuilder-controller | AG10: 78 | AH10: 56.4 | AI10: =IF(J10=J9,AI9+1,J10) -> 52
A11: 46218.887 | B11: scale-burst | C11: crossplane | D11: 50 | E11: 230 | F11: 190 | G11: 46218.887 | H11: scale-burst | I11: crossplane | J11: 50 | K11: 59 | L11: 54 | M11: 46218.887 | N11: scale-burst | O11: crossplane | P11: 50 | Q11: 39 | R11: 71 | S11: 46218.887 | T11: scale-burst | U11: crossplane | V11: 50 | W11: provider-kubernetes | X11: 88 | Y11: 74 | Z11: =E11+K11+Q11+X11 -> 416 | AA11: =F11+L11+R11+Y11 -> 389 | AB11: 46218.924 | AC11: scale-burst | AD11: kubebuilder | AE11: 50 | AF11: kubebuilder-controller | AG11: 89 | AH11: 56.5 | AI11: =IF(J11=J10,AI10+1,J11) -> 53
A12: 46218.887 | B12: scale-burst | C12: crossplane | D12: 50 | E12: 230 | F12: 190 | G12: 46218.887 | H12: scale-burst | I12: crossplane | J12: 50 | K12: 59 | L12: 54 | M12: 46218.887 | N12: scale-burst | O12: crossplane | P12: 50 | Q12: 39 | R12: 71 | S12: 46218.887 | T12: scale-burst | U12: crossplane | V12: 50 | W12: provider-kubernetes | X12: 88 | Y12: 74 | Z12: =E12+K12+Q12+X12 -> 416 | AA12: =F12+L12+R12+Y12 -> 389 | AB12: 46218.924 | AC12: scale-burst | AD12: kubebuilder | AE12: 50 | AF12: kubebuilder-controller | AG12: 59 | AH12: 56.5 | AI12: =IF(J12=J11,AI11+1,J12) -> 54
A13: 46218.888 | B13: scale-burst | C13: crossplane | D13: 100 | E13: 29 | F13: 192 | G13: 46218.888 | H13: scale-burst | I13: crossplane | J13: 100 | K13: 2 | L13: 54 | M13: 46218.888 | N13: scale-burst | O13: crossplane | P13: 100 | Q13: 51 | R13: 71 | S13: 46218.888 | T13: scale-burst | U13: crossplane | V13: 100 | W13: provider-kubernetes | X13: 100 | Y13: 75 | Z13: =E13+K13+Q13+X13 -> 182 | AA13: =F13+L13+R13+Y13 -> 392 | AB13: 46218.924 | AC13: scale-burst | AD13: kubebuilder | AE13: 50 | AF13: kubebuilder-controller | AG13: 69 | AH13: 56.5 | AI13: =IF(J13=J12,AI12+1,J13) -> 100
A14: 46218.888 | B14: scale-burst | C14: crossplane | D14: 100 | E14: 39 | F14: 193 | G14: 46218.888 | H14: scale-burst | I14: crossplane | J14: 100 | K14: 2 | L14: 54 | M14: 46218.888 | N14: scale-burst | O14: crossplane | P14: 100 | Q14: 51 | R14: 71 | S14: 46218.888 | T14: scale-burst | U14: crossplane | V14: 100 | W14: provider-kubernetes | X14: 100 | Y14: 75 | Z14: =E14+K14+Q14+X14 -> 192 | AA14: =F14+L14+R14+Y14 -> 393 | AB14: 46218.924 | AC14: scale-burst | AD14: kubebuilder | AE14: 50 | AF14: kubebuilder-controller | AG14: 78 | AH14: 56.5 | AI14: =IF(J14=J13,AI13+1,J14) -> 101
A15: 46218.888 | B15: scale-burst | C15: crossplane | D15: 100 | E15: 39 | F15: 193 | G15: 46218.888 | H15: scale-burst | I15: crossplane | J15: 100 | K15: 37 | L15: 54 | M15: 46218.888 | N15: scale-burst | O15: crossplane | P15: 100 | Q15: 35 | R15: 71 | S15: 46218.888 | T15: scale-burst | U15: crossplane | V15: 100 | W15: provider-kubernetes | X15: 75 | Y15: 75 | Z15: =E15+K15+Q15+X15 -> 186 | AA15: =F15+L15+R15+Y15 -> 393 | AB15: 46218.924 | AC15: scale-burst | AD15: kubebuilder | AE15: 50 | AF15: kubebuilder-controller | AG15: 79 | AH15: 56.6 | AI15: =IF(J15=J14,AI14+1,J15) -> 102
... A137: 46218.906 | B137: scale-burst | C137: crossplane | D137: 1000 | E137: 388 | F137: 646 | G137: 46218.906 | H137: scale-burst | I137: crossplane | J137: 1000 | K137: 115 | L137: 39 | M137: 46218.906 | N137: scale-burst | O137: crossplane | P137: 1000 | Q137: 44 | R137: 125 | S137: 46218.906 | T137: scale-burst | U137: crossplane | V137: 1000 | W137: provider-kubernetes | X137: 20 | Y137: 160 | Z137: =E137+K137+Q137+X137 -> 567 | AA137: =F137+L137+R137+Y137 -> 970 | AB137: 46218.928 | AC137: scale-burst | AD137: kubebuilder | AE137: 500 | AF137: kubebuilder-controller | AG137: 109 | AH137: 63.7 | AI137: =IF(J137=J136,AI136+1,J137) -> 1076
A138: 46218.906 | B138: scale-burst | C138: crossplane | D138: 1000 | E138: 377 | F138: 622 | M138: 46218.906 | N138: scale-burst | O138: crossplane | P138: 1000 | Q138: 47 | R138: 125 | Z138: =E138+K138+Q138+X138 -> 424 | AA138: =F138+L138+R138+Y138 -> 747 | AB138: 46218.928 | AC138: scale-burst | AD138: kubebuilder | AE138: 500 | AF138: kubebuilder-controller | AG138: 127 | AH138: 63.7 | AI138: =IF(J138=J137,AI137+1,J138) -> 0
A139: 46218.906 | B139: scale-burst | C139: crossplane | D139: 1000 | E139: 377 | F139: 622 | M139: 46218.906 | N139: scale-burst | O139: crossplane | P139: 1000 | Q139: 47 | R139: 125 | Z139: =E139+K139+Q139+X139 -> 424 | AA139: =F139+L139+R139+Y139 -> 747 | AB139: 46218.928 | AC139: scale-burst | AD139: kubebuilder | AE139: 500 | AF139: kubebuilder-controller | AG139: 99 | AH139: 63.7 | AI139: =IF(J139=J138,AI138+1,J139) -> 1
AB140: 46218.929 | AC140: scale-burst | AD140: kubebuilder | AE140: 500 | AF140: kubebuilder-controller | AG140: 99 | AH140: 63.7 | AI140: =IF(J140=J139,AI139+1,J140) -> 2
AB141: 46218.929 | AC141: scale-burst | AD141: kubebuilder | AE141: 500 | AF141: kubebuilder-controller | AG141: 99 | AH141: 63.7 | AI141: =IF(J141=J140,AI140+1,J141) -> 3
AB142: 46218.929 | AC142: scale-burst | AD142: kubebuilder | AE142: 500 | AF142: kubebuilder-controller | AG142: 99 | AH142: 63.7 | AI142: =IF(J142=J141,AI141+1,J142) -> 4
AB143: 46218.929 | AC143: scale-burst | AD143: kubebuilder | AE143: 500 | AF143: kubebuilder-controller | AG143: 119 | AH143: 63.7 | AI143: =IF(J143=J142,AI142+1,J143) -> 5
AB144: 46218.929 | AC144: scale-burst | AD144: kubebuilder | AE144: 500 | AF144: kubebuilder-controller | AG144: 99 | AH144: 63.7 | AI144: =IF(J144=J143,AI143+1,J144) -> 6
AB145: 46218.929 | AC145: scale-burst | AD145: kubebuilder | AE145: 500 | AF145: kubebuilder-controller | AG145: 118 | AH145: 65.8 | AI145: =IF(J145=J144,AI144+1,J145) -> 7
AB146: 46218.929 | AC146: scale-burst | AD146: kubebuilder | AE146: 500 | AF146: kubebuilder-controller | AG146: 99 | AH146: 65.8 | AI146: =IF(J146=J145,AI145+1,J146) -> 8
AB147: 46218.929 | AC147: scale-burst | AD147: kubebuilder | AE147: 500 | AF147: kubebuilder-controller | AG147: 108 | AH147: 65.8 | AI147: =IF(J147=J146,AI146+1,J147) -> 9
AB148: 46218.929 | AC148: scale-burst | AD148: kubebuilder | AE148: 500 | AF148: kubebuilder-controller | AG148: 108 | AH148: 65.8 | AI148: =IF(J148=J147,AI147+1,J148) -> 10
AB149: 46218.929 | AC149: scale-burst | AD149: kubebuilder | AE149: 500 | AF149: kubebuilder-controller | AG149: 109 | AH149: 65.8 | AI149: =IF(J149=J148,AI148+1,J149) -> 11
AB150: 46218.929 | AC150: scale-burst | AD150: kubebuilder | AE150: 500 | AF150: kubebuilder-controller | AG150: 109 | AH150: 65.8 | AI150: =IF(J150=J149,AI149+1,J150) -> 12
AB151: 46218.929 | AC151: scale-burst | AD151: kubebuilder | AE151: 500 | AF151: kubebuilder-controller | AG151: 109 | AH151: 65.8 | AI151: =IF(J151=J150,AI150+1,J151) -> 13
... AB380: 46218.935 | AC380: scale-burst | AD380: kubebuilder | AE380: 1000 | AF380: kubebuilder-controller | AG380: 69 | AH380: 76.4 | AI380: =IF(J380=J379,AI379+1,J380) -> 242

Sheet memory graphs (2)
A1: N/ram_mibs | B1: crossplane_core | C1: function-patch-and-transform | D1: provider-kafka | E1: provider-kubernetes | F1: Crossplane | G1: Kubebuilder
A2: 1 | B2: =AVERAGE(dati!F3:F4) -> 187 | C2: =AVERAGE(dati!L3:L4) -> 52 | D2: =AVERAGE(dati!$R$3:$R$4) -> 71 | E2: =AVERAGE(dati!$Y$3:$Y$4) -> 74 | F2: =AVERAGE(dati!$AA$3:$AA$4) -> 384 | G2: 51.2
A3: 10 | B3: =AVERAGE(dati!F$5:F$7) -> 187 | C3: =AVERAGE(dati!L5:L7) -> 52 | D3: =AVERAGE(dati!$R$5:$R$7) -> 71 | E3: =AVERAGE(dati!$Y$5:$Y$7) -> 74 | F3: =AVERAGE(dati!$AA$5:$AA$7) -> 384 | G3: =AVERAGE(dati!AH3:AH5) -> 56.1
A4: 50 | B4: =AVERAGE(dati!$F$8:$F$12) -> 188.8 | C4: =AVERAGE(dati!$L$8:$L$12) -> 53.8 | D4: =AVERAGE(dati!$R$8:$R$12) -> 71 | E4: =AVERAGE(dati!$Y$8:$Y$12) -> 74 | F4: =AVERAGE(dati!$AA$8:$AA$12) -> 387.6 | G4: =AVERAGE(dati!AH6:AH19) -> 56.485714
A5: 100 | B5: =AVERAGE(dati!$F$13:$F$23) -> 204.09091 | C5: =AVERAGE(dati!$L$13:$L$23) -> 53.818182 | D5: =AVERAGE(dati!$R$13:$R$23) -> 71 | E5: =AVERAGE(dati!$Y$13:$Y$23) -> 77.272727 | F5: =AVERAGE(dati!$AA$13:$AA$23) -> 406.18182 | G5: =AVERAGE(dati!AH20:AH57) -> 56.873684
A6: 500 | B6: =AVERAGE(dati!$F$24:$F$60) -> 292.18919 | C6: =AVERAGE(dati!$L$24:$L$60) -> 42.459459 | D6: =AVERAGE(dati!$R$24:$R$60) -> 73.783784 | E6: =AVERAGE(dati!$Y$24:$Y$60) -> 93.216216 | F6: =AVERAGE(dati!$AA$24:$AA$60) -> 501.64865 | G6: =AVERAGE(dati!AH58:AH167) -> 61.172727
A7: 1000 | B7: =AVERAGE(dati!$F$61:$F$139) -> 373.70886 | C7: =AVERAGE(dati!$L$61:$L$139) -> 32.519481 | D7: =AVERAGE(dati!$R$61:$R$139) -> 84.075949 | E7: =AVERAGE(dati!$Y$61:$Y$139) -> 114.96104 | F7: =AVERAGE(dati!$AA$61:$AA$139) -> 601.53165 | G7: =AVERAGE(dati!AH168:AH380) -> 66.514554
E33: X-axis: batch size, the number of DataStream resources created together (N)
E34: Y-axis: average CPU rate (millicores) each component sustained while it was actively reconciling that batch
B49: Crossplane CPU grows with larger batches because each DataStream triggers a multi-controller pipeline (claim/XR + composition function + provider-kafka + provider-kubernetes), so when queue depth increases, more controllers are actively reconciling and CPU rises.

Sheet cpu graphs
A1: N/cpu_millicores | B1: crossplane_core | C1: function-patch-and-transform | D1: provider-kafka | E1: provider-kubernetes | F1: Crossplane | G1: Kubebuilder
A2: 1 | B2: =AVERAGE(dati!$E$3:$E$4) -> 2 | C2: =AVERAGE(dati!$K$3:$K$4) -> 0 | D2: =AVERAGE(dati!$Q$3:$Q$4) -> 2 | E2: =AVERAGE(dati!$X$3:$X$4) -> 2 | F2: =AVERAGE(dati!$Z$3:$Z$4) -> 6 | G2: 40
A3: 10 | B3: =AVERAGE(dati!$E$5:$E$7) -> 3.3333333 | C3: =AVERAGE(dati!$K$5:$K$7) -> 2.6666667 | D3: =AVERAGE(dati!$Q$5:$Q$7) -> 3 | E3: =AVERAGE(dati!$X$5:$X$7) -> 5 | F3: =AVERAGE(dati!$Z$5:$Z$7) -> 14 | G3: =AVERAGE(dati!AG3:AG5) -> 75.333333
A4: 50 | B4: =AVERAGE(dati!$E$8:$E$12) -> 99.8 | C4: =AVERAGE(dati!$K$8:$K$12) -> 33.4 | D4: =AVERAGE(dati!$Q$8:$Q$12) -> 21.4 | E4: =AVERAGE(dati!$X$8:$X$12) -> 70.8 | F4: =AVERAGE(dati!$Z$8:$Z$12) -> 225.4 | G4: =AVERAGE(dati!AG6:AG19) -> 73.785714
A5: 100 | B5: =AVERAGE(dati!$E$13:$E$23) -> 158 | C5: =AVERAGE(dati!$K$13:$K$23) -> 46.454545 | D5: =AVERAGE(dati!$Q$13:$Q$23) -> 36.636364 | E5: =AVERAGE(dati!$X$13:$X$23) -> 94.090909 | F5: =AVERAGE(dati!$Z$13:$Z$23) -> 335.18182 | G5: =AVERAGE(dati!AG20:AG57) -> 49.894737
A6: 500 | B6: =AVERAGE(dati!$E$24:$E$60) -> 267.43243 | C6: =AVERAGE(dati!$K$24:$K$60) -> 64.594595 | D6: =AVERAGE(dati!$Q$24:$Q$60) -> 48.027027 | E6: =AVERAGE(dati!$X$24:$X$60) -> 117.89189 | F6: =AVERAGE(dati!$Z$24:$Z$60) -> 497.94595 | G6: =AVERAGE(dati!AG58:AG167) -> 91.390909
A7: 1000 | B7: =AVERAGE(dati!$E$61:$E$139) -> 267.65823 | C7: =AVERAGE(dati!$K$61:$K$139) -> 65.922078 | D7: =AVERAGE(dati!$Q$61:$Q$139) -> 53.531646 | E7: =AVERAGE(dati!$X$61:$X$139) -> 116.23377 | F7: =AVERAGE(dati!$Z$61:$Z$139) -> 498.73418 | G7: =AVERAGE(dati!AG168:AG380) -> 101.97183
B11: CPU vs # DataStream custom resources
A18: That's not noise, that's a ceiling. This lines up with something worth checking against your "internal optimizations" slide: Crossplane providers apply rate-limiting on their reconcile queues, so past a certain point more resources don't mean more CPU — they just mean a longer queue, not more instantaneous work. This is a genuinely good finding for your report, not just a number.
A20: At N=10, Kubebuilder is actually more CPU-hungry than Crossplane (75m vs 14m) — Crossplane hasn't ramped up yet. But by N=500-1000, Crossplane costs ~5x more CPU than Kubebuilder (498m vs ~100m). That's a strong, concrete data point for your "Provisioning latency / Kubebuilder: fewer controller layers" row in your decision table — you now have a number behind that claim instead of just an architectural argument.
B49: Crossplane CPU grows with larger batches because each DataStream triggers a multi-controller pipeline (claim/XR + composition function + provider-kafka + provider-kubernetes), so when queue depth increases, more controllers are actively reconciling and CPU rises.
D57: X-axis: batch size, the number of DataStream resources created together (N)
D58: Y-axis: average CPU rate (millicores) each component sustained while it was actively reconciling that batch
F64: 1.7321429
B66: rest | C66: cp | D66: kb
B67: cpu | C67: 7 | D67: =AVERAGE(rest!P7:P62) -> 1.7321429
B68: ram | C68: 384 | D68: =AVERAGE(rest!G3:G14) -> 187

Sheet samples1000kb
A1: timestamp | B1: mode | C1: framework | D1: n_resources | E1: component | F1: cpu_millicores | G1: mem_mib
A2: 2026-07-15T19:11:37+00:00 | B2: at-rest | C2: all | D2: 0 | E2: crossplane-core | F2: 3 | G2: 187
A3: 2026-07-15T19:11:38+00:00 | B3: at-rest | C3: all | D3: 0 | E3: provider-kafka | F3: 2 | G3: 71
A4: 2026-07-15T19:11:38+00:00 | B4: at-rest | C4: all | D4: 0 | E4: provider-kubernetes | F4: 2 | G4: 74
A5: 2026-07-15T19:11:38+00:00 | B5: at-rest | C5: all | D5: 0 | E5: function-patch-and-transform | F5: 1 | G5: 52
A6: 2026-07-15T19:11:39+00:00 | B6: at-rest | C6: all | D6: 0 | E6: kubebuilder-controller | F6: 0 | G6: 51.5
A7: 2026-07-15T19:11:45+00:00 | B7: at-rest | C7: all | D7: 0 | E7: crossplane-core | F7: 3 | G7: 187
A8: 2026-07-15T19:11:45+00:00 | B8: at-rest | C8: all | D8: 0 | E8: provider-kafka | F8: 2 | G8: 71
A9: 2026-07-15T19:11:45+00:00 | B9: at-rest | C9: all | D9: 0 | E9: provider-kubernetes | F9: 2 | G9: 74
A10: 2026-07-15T19:11:46+00:00 | B10: at-rest | C10: all | D10: 0 | E10: function-patch-and-transform | F10: 1 | G10: 52
A11: 2026-07-15T19:11:46+00:00 | B11: at-rest | C11: all | D11: 0 | E11: kubebuilder-controller | F11: 0 | G11: 51.5
A12: 2026-07-15T19:11:52+00:00 | B12: at-rest | C12: all | D12: 0 | E12: crossplane-core | F12: 3 | G12: 187
A13: 2026-07-15T19:11:52+00:00 | B13: at-rest | C13: all | D13: 0 | E13: provider-kafka | F13: 2 | G13: 71
... A1343: 2026-07-15T20:27:17+00:00 | B1343: scale | C1343: kubebuilder | D1343: 1000 | E1343: kubebuilder-controller | F1343: 0 | G1343: 78.9
